Workbook

Sheet Sheet2
A1: cutoff | B1: 8
A2: Database | B2: RTE scenarios
A3: format | B3: Excel spreadsheet
A7: Activity | B7: market for electricity, low voltage M0
A8: production amount | B8: 1
A9: comment | B9: RTE scenarios adapted from Ecoinvent - no background data altered
A10: reference product | B10: electricity, high voltage
A11: location | B11: FR
A12: unit | B12: kWh
A13: Exchanges
A14: name | B14: amount | C14: location | D14: unit | E14: categories | F14: type | G14: reference product | H14: comment
A15: =B7 -> market for electricity, low voltage M0 | B15: 1 | C15: FR | D15: kWh | F15: production | G15: =B10 -> electricity, high voltage
A16: electricity production, hydro, reservoir, alpine region | B16: =Sheet1!L38*Sheet1!L40*(hydro!G13+hydro!G13*Sheet1!L37) -> 0.016529067 | C16: FR | D16: kWh | F16: technosphere | G16: electricity, high voltage
A17: electricity production, hydro, run-of-river | B17: =Sheet1!L38*Sheet1!L40*(hydro!G14+hydro!G14*Sheet1!L37) -> 0.086780036 | C17: FR | D17: kWh | F17: technosphere | G17: electricity, high voltage
A18: electricity production, wind, 1-3MW turbine, onshore | B18: =Sheet1!L38*Sheet1!L40*(Wind!G13+Wind!G13*Sheet1!L37) -> 0.18090965 | C18: FR | D18: kWh | F18: technosphere | G18: electricity, high voltage
A19: electricity production, wind, <1MW turbine, onshore | B19: =Sheet1!L38*Sheet1!L40*(Wind!G14+Wind!G14*Sheet1!L37) -> 0.011626813 | C19: FR | D19: kWh | F19: technosphere | G19: electricity, high voltage
A20: electricity production, wind, >3MW turbine, onshore | B20: =Sheet1!L38*Sheet1!L40*(Wind!G15+Wind!G15*Sheet1!L37) -> 0.00074735902 | C20: FR | D20: kWh | F20: technosphere | G20: electricity, high voltage
A21: electricity production, wind, 1-3MW turbine, offshore | B21: =Sheet1!L38*Sheet1!L40*(Wind!G26+Wind!G26*Sheet1!L37) -> 0.11573727 | C21: FR | D21: kWh | F21: technosphere | G21: electricity, high voltage
A22: electricity production, wind, 1-3MW turbine, offshore | B22: =Sheet1!L38*Sheet1!L40*(Wind!G27+Wind!G27*Sheet1!L37) -> 0.1736059 | C22: FR | D22: kWh | F22: technosphere | G22: electricity, high voltage | H22: proxy for flotant: data provided by Tsai et al. 2016 for fixed foundations of 3 MW wind turbines and Weinzettel et al., 2008 for a spar floating foundations of 5 MW wind turbines.
A23: heat and power co-generation, biogas, gas engine | B23: =Sheet1!L38*Sheet1!L40*(Biogas!F6+Biogas!F6*Sheet1!L37) -> 0.012687083 | C23: FR | D23: kWh | F23: technosphere | G23: electricity, high voltage
A24: market for electricity, high voltage | B24: =Sheet1!L38*Sheet1!L40*(Sheet1!AI26+Sheet1!AI26*Sheet1!L37) -> 0.073015456 | C24: IS | D24: kWh | F24: technosphere | G24: electricity, high voltage | H24: proxy for the rest
A25: electricity, high voltage, import from IT | B25: =Sheet1!L38*Sheet1!L40*(imports!N3+imports!N3*Sheet1!L37) -> 0.0037662235 | C25: FR | D25: kWh | F25: technosphere | G25: electricity, high voltage
A26: electricity, high voltage, import from GB | B26: =Sheet1!L38*Sheet1!L40*(imports!O3+imports!O3*Sheet1!L37) -> 0.0028222467 | C26: FR | D26: kWh | F26: technosphere | G26: electricity, high voltage
A27: electricity, high voltage, import from DE | B27: =Sheet1!L38*Sheet1!L40*(imports!P3+imports!P3*Sheet1!L37) -> 0.0098275048 | C27: FR | D27: kWh | F27: technosphere | G27: electricity, high voltage
A28: electricity, high voltage, import from CH | B28: =Sheet1!L38*Sheet1!L40*(imports!Q3+imports!Q3*Sheet1!L37) -> 0.018242329 | C28: FR | D28: kWh | F28: technosphere | G28: electricity, high voltage
A29: electricity, high voltage, import from BE | B29: =Sheet1!L38*Sheet1!L40*(imports!R3+imports!R3*Sheet1!L37) -> 0.015220178 | C29: FR | D29: kWh | F29: technosphere | G29: electricity, high voltage
A30: electricity, high voltage, import from ES | B30: =Sheet1!L38*Sheet1!L40*(imports!S3+imports!S3*Sheet1!L37) -> 0.012364779 | C30: FR | D30: kWh | F30: technosphere | G30: electricity, high voltage
A31: electricity production, photovoltaic, 3kWp slanted-roof installation, multi-Si, panel, mounted | B31: =Solar!H11+Solar!H11*Sheet1!L41 -> 0.071302865 | C31: FR | D31: kWh | F31: technosphere | G31: electricity, low voltage
A32: electricity production, photovoltaic, 3kWp slanted-roof installation, single-Si, panel, mounted | B32: =Solar!H12+Solar!H12*Sheet1!L41 -> 0.057329337 | C32: FR | D32: kWh | F32: technosphere | G32: electricity, low voltage
A33: electricity production, photovoltaic, 570kWp open ground installation, multi-Si | B33: =Solar!H13+Solar!H13*Sheet1!L41 -> 0.18866056 | C33: FR | D33: kWh | F33: technosphere | G33: electricity, low voltage
A34: market for transmission network, electricity, high voltage direct current aerial line | B34: =Sheet1!L38*Sheet1!L40*(Sheet1!AK28+Sheet1!AK28*Sheet1!L37) -> 6.052007e-09 | C34: GLO | D34: km | F34: technosphere | G34: transmission network, electricity, high voltage direct current aerial line
A35: market for transmission network, electricity, high voltage direct current land cable | B35: =Sheet1!L38*Sheet1!L40*(Sheet1!AK29+Sheet1!AK29*Sheet1!L37) -> 4.1330645e-10 | C35: GLO | D35: km | F35: technosphere | G35: transmission network, electricity, high voltage direct current land cable
A36: market for transmission network, electricity, high voltage direct current subsea cable | B36: =Sheet1!L38*Sheet1!L40*(Sheet1!AK30+Sheet1!AK30*Sheet1!L37) -> 3.7186332e-12 | C36: GLO | D36: km | F36: technosphere | G36: transmission network, electricity, high voltage direct current subsea cable
A37: market for transmission network, electricity, medium voltage | B37: =Sheet1!L40*(Sheet1!AK31+Sheet1!AK31*Sheet1!L39) -> 1.9284894e-08 | C37: GLO | D37: km | F37: technosphere | G37: transmission network, electricity, medium voltage
A38: market for distribution network, electricity, low voltage | B38: =Sheet1!AK32+Sheet1!AK32*Sheet1!L41 -> 9.0088048e-08 | C38: GLO | D38: km | F38: technosphere | G38: distribution network, electricity, low voltage
A39: market for sulfur hexafluoride, liquid | B39: =Sheet1!L38*(Sheet1!Q29+Sheet1!Q29*Sheet1!L39)+Sheet1!L40*(Sheet1!Q33+Sheet1!Q33*Sheet1!L41) -> 5.5019118e-08 | C39: RER | D39: kg | F39: technosphere | G39: sulfur hexafluoride, liquid
A40: market for water, deionised | B40: =Sheet1!AE18*14 -> 27.094985 | C40: Europe without Switzerland | D40: kg | F40: technosphere | G40: water, deionised | H40: water to adjust the proxy value used in "rest" based on the hydrogen percentage
A43: Activity | B43: market for electricity, low voltage M1
A44: production amount | B44: 1
A45: comment | B45: RTE scenarios adapted from Ecoinvent - no background data altered
...

Sheet Sheet1
A1: skip
B2: Percentage | L2: Installed capacity (GW) | V2: Production (TWh) | AB2: Bioenergy | AC2: Battery | AD2: tidal | AE2: hydrogen | AF2: rest
B3: New Nuclear | C3: Existing Nuclear | D3: Solar | E3: Land Wind (onshore) | F3: Sea Wind (offshore) | G3: Hydropower | H3: Rest | I3: Total | L3: NN | M3: EN | N3: S | O3: LW | P3: SW | Q3: H | R3: R | S3: T | V3: NN | W3: EN | X3: S | Y3: LW | Z3: SW | AA3: H | AB3: BG | AC3: BE | AD3: T | AE3: H | AF3: R | AG3: Exp | AH3: Imp | AI3: Total | AJ3: Total-expot | AL3: NN | AM3: EN | AN3: S | AO3: LW | AP3: SW | AQ3: H | AR3: R | AS3: T
A4: M0 | B4: 0 | C4: 0 | D4: 36 | E4: 21 | F4: 31 | G4: 9 | H4: =100-(B4+C4+D4+E4+F4+G4) -> 3 | I4: =SUM(B4:H4) -> 100 | K4: M0 | L4: 0 | M4: 0 | N4: 208 | O4: 74 | P4: 62 | Q4: 30.1 | S4: =SUM(L4:R4) -> 374.1 | U4: M0 | V4: 0 | W4: 0 | X4: 254.5 | Y4: 149.3 | Z4: 223.5 | AA4: 79.8 | AB4: 9.8 | AC4: 27.5 | AD4: 8.7 | AE4: 16 | AF4: =1.9+1.8+0.5 -> 4.2 | AG4: 64 | AH4: 49 | AI4: =SUM(V4:AF4) -> 773.3 | AJ4: =AI4-AG4 -> 709.3 | AL4: =L4*$AL$18*$AL$19*$AL$21 -> 0 | AM4: =M4*$AL$18*$AL$19*$AL$21*0.001 -> 0 | AN4: =N4*$AL$18*$AL$19*$AL$23*0.001 -> 254.18016 | AO4: =O4*$AL$18*$AL$19*$AL$24*0.001 -> 149.0952 | AP4: =P4*$AL$18*$AL$19*$AL$25*0.001 -> 223.76544 | AQ4: =22*$AL$18*$AL$19*$AL$26*0.001 -> 79.0152 | AS4: =SUM(AL4:AR4) -> 706.056
A5: M1 | B5: 0 | C5: 13 | D5: 36 | E5: 17 | F5: 23 | G5: 9 | H5: =100-(B5+C5+D5+E5+F5+G5) -> 2 | I5: =SUM(B5:H5) -> 100 | K5: M1 | L5: 0 | M5: 15.5 | N5: 214 | O5: 59 | P5: 45 | Q5: 30.1 | S5: =SUM(L5:R5) -> 363.6 | U5: M1 | V5: 0 | W5: 90.7 | X5: 254.9 | Y5: 118.7 | Z5: 162.4 | AA5: 79.5 | AB5: 9.8 | AC5: 21.7 | AD5: 2.9 | AE5: 10.5 | AF5: =1.9+1.8+0.5 -> 4.2 | AG5: 65 | AH5: 42 | AI5: =SUM(V5:AF5) -> 755.3 | AJ5: =AI5-AG5 -> 690.3 | AL5: =L5*$AL$18*$AL$19*$AL$21 -> 0 | AM5: =M5*$AL$18*$AL$19*$AL$21*0.001 -> 95.046 | AN5: =N5*$AL$18*$AL$19*$AL$23*0.001 -> 261.51228 | AO5: =O5*$AL$18*$AL$19*$AL$24*0.001 -> 118.8732 | AP5: =P5*$AL$18*$AL$19*$AL$25*0.001 -> 162.4104 | AQ5: =22*$AL$18*$AL$19*$AL$26*0.001 -> 79.0152 | AS5: =SUM(AL5:AR5) -> 716.85708
A6: M23 | B6: 0 | C6: 13 | D6: 22 | E6: 21 | F6: 32 | G6: 9 | H6: =100-(B6+C6+D6+E6+F6+G6) -> 3 | I6: =SUM(B6:H6) -> 100 | K6: M23 | L6: 0 | M6: 15.5 | N6: 125 | O6: 72 | P6: 60 | Q6: 30.1 | S6: =SUM(L6:R6) -> 302.6 | U6: M23 | V6: 0 | W6: 91.1 | X6: 153 | Y6: 145.3 | Z6: 215.3 | AA6: 78.2 | AB6: 9.8 | AC6: 11.8 | AD6: 8.7 | AE6: 8.9 | AF6: =1.9+1.8+0.5 -> 4.2 | AG6: 69 | AH6: 41 | AI6: =SUM(V6:AF6) -> 726.3 | AJ6: =AI6-AG6 -> 657.3 | AL6: =L6*$AL$18*$AL$19*$AL$21 -> 0 | AM6: =M6*$AL$18*$AL$19*$AL$21*0.001 -> 95.046 | AN6: =N6*$AL$18*$AL$19*$AL$23*0.001 -> 152.7525 | AO6: =O6*$AL$18*$AL$19*$AL$24*0.001 -> 145.0656 | AP6: =P6*$AL$18*$AL$19*$AL$25*0.001 -> 216.5472 | AQ6: =22*$AL$18*$AL$19*$AL$26*0.001 -> 79.0152 | AS6: =SUM(AL6:AR6) -> 688.4265
A7: N1 | B7: 12 | C7: 14 | D7: 22 | E7: 17 | F7: 24 | G7: 9 | H7: =100-(B7+C7+D7+E7+F7+G7) -> 2 | I7: =SUM(B7:H7) -> 100 | K7: N1 | L7: 13.2 | M7: 15.5 | N7: 118 | O7: 58 | P7: 45 | Q7: 30.1 | S7: =SUM(L7:R7) -> 279.8 | U7: N1 | V7: 89.6 | W7: 92.4 | X7: 144.4 | Y7: 117.3 | Z7: 160.2 | AA7: 77.9 | AB7: 9.8 | AC7: 7.7 | AD7: 0 | AE7: 5.7 | AF7: =1.9+1.8+0.5 -> 4.2 | AG7: 52 | AH7: 33 | AI7: =SUM(V7:AF7) -> 709.2 | AJ7: =AI7-AG7 -> 657.2 | AL7: =L7*$AL$18*$AL$19*$AL$22*0.001 -> 90.19296 | AM7: =M7*$AL$18*$AL$19*$AL$21*0.001 -> 95.046 | AN7: =N7*$AL$18*$AL$19*$AL$23*0.001 -> 144.19836 | AO7: =O7*$AL$18*$AL$19*$AL$24*0.001 -> 116.8584 | AP7: =P7*$AL$18*$AL$19*$AL$25*0.001 -> 162.4104 | AQ7: =22*$AL$18*$AL$19*$AL$26*0.001 -> 79.0152 | AS7: =SUM(AL7:AR7) -> 687.72132
A8: N2 | B8: 14 | C8: 22 | D8: 17 | E8: 16 | F8: 20 | G8: 9 | H8: =100-(B8+C8+D8+E8+F8+G8) -> 2 | I8: =SUM(B8:H8) -> 100 | K8: N2 | L8: 23.2 | M8: 15.5 | N8: 90 | O8: 51.5 | P8: 36.1 | Q8: 30.1 | S8: =SUM(L8:R8) -> 246.4 | U8: N2 | V8: 159.3 | W8: 93.1 | X8: 110.1 | Y8: 103.8 | Z8: 129.1 | AA8: 76.9 | AB8: 9.8 | AC8: 0.2 | AD8: 0 | AE8: 1.9 | AF8: =1.8+0.1+1.8+0.4 -> 4.1 | AG8: 49 | AH8: 28 | AI8: =SUM(V8:AF8) -> 688.3 | AJ8: =AI8-AG8 -> 639.3 | AL8: =L8*$AL$18*$AL$19*$AL$22*0.001 -> 158.52096 | AM8: =M8*$AL$18*$AL$19*$AL$21*0.001 -> 95.046 | AN8: =N8*$AL$18*$AL$19*$AL$23*0.001 -> 109.9818 | AO8: =O8*$AL$18*$AL$19*$AL$24*0.001 -> 103.7622 | AP8: =P8*$AL$18*$AL$19*$AL$25*0.001 -> 130.28923 | AQ8: =22*$AL$18*$AL$19*$AL$26*0.001 -> 79.0152 | AS8: =SUM(AL8:AR8) -> 676.61539
A9: N03 | B9: 23 | C9: 27 | D9: 13 | E9: 12 | F9: 12 | G9: 10 | H9: =100-(B9+C9+D9+E9+F9+G9) -> 3 | I9: =SUM(B9:H9) -> 100 | K9: N03 | L9: =23.2+4.1 -> 27.3 | M9: 24.4 | N9: 70 | O9: 43 | P9: 22 | Q9: 30.1 | S9: =SUM(L9:R9) -> 216.8 | U9: N03 | V9: =162.3+27 -> 189.3 | W9: 149.2 | X9: 85.7 | Y9: 86.7 | Z9: 77.9 | AA9: 75.2 | AB9: 9.8 | AC9: 0 | AD9: 0 | AE9: 0 | AF9: =1.8+1.8 -> 3.6 | AG9: 43 | AH9: 26 | AI9: =SUM(V9:AF9) -> 677.4 | AJ9: =AI9-AG9 -> 634.4 | AL9: =23.2*$AL$18*$AL$19*$AL$22*0.001+4.1*$AL$18*$AL$19*AM22*0.001 -> 189.22914 | AM9: =L9*$AL$18*$AL$19*$AL$21*0.001 -> 167.4036 | AN9: =N9*$AL$18*$AL$19*$AL$23*0.001 -> 85.5414 | AO9: =O9*$AL$18*$AL$19*$AL$24*0.001 -> 86.6364 | AP9: =P9*$AL$18*$AL$19*$AL$25*0.001 -> 79.40064 | AQ9: =22*$AL$18*$AL$19*$AL$26*0.001 -> 79.0152 | AS9: =SUM(AL9:AR9) -> 687.22638
V11: =V4*$AJ$4/$AI$4 -> 0 | W11: =W4*$AJ$4/$AI$4 -> 0 | X11: =X4*$AJ$4/$AI$4 -> 233.43702 | Y11: =Y4*$AJ$4/$AI$4 -> 136.94361 | Z11: =Z4*$AJ$4/$AI$4 -> 205.00265 | AA11: =AA4*$AJ$4/$AI$4 -> 73.195577 | AB11: =AB4*$AJ$4/$AI$4 -> 8.9889306 | AC11: =AC4*$AJ$4/$AI$4 -> 25.22404 | ... AF11: =AF4*$AJ$4/$AI$4 -> 3.8523988 | AH11: 49 | AI11: =SUM(V11:AH11) -> 758.3
V12: =V5*$AJ$4/$AI$4 -> 0 | W12: =W5*$AJ$4/$AI$4 -> 83.19347 | X12: =X5*$AJ$4/$AI$4 -> 233.80392 | Y12: =Y5*$AJ$4/$AI$4 -> 108.87613 | Z12: =Z5*$AJ$4/$AI$4 -> 148.95942 | AA12: =AA5*$AJ$4/$AI$4 -> 72.920406 | AB12: =AB5*$AJ$4/$AI$4 -> 8.9889306 | AC12: =AC5*$AJ$4/$AI$4 -> 19.904061 | ... AF12: =AF5*$AJ$4/$AI$4 -> 3.8523988 | AH12: 42 | AI12: =SUM(V12:AH12) -> 734.78972
V13: =V6*$AJ$4/$AI$4 -> 0 | W13: =W6*$AJ$4/$AI$4 -> 83.560365 | X13: =X6*$AJ$4/$AI$4 -> 140.33739 | Y13: =Y6*$AJ$4/$AI$4 -> 133.27465 | Z13: =Z6*$AJ$4/$AI$4 -> 197.4813 | AA13: =AA6*$AJ$4/$AI$4 -> 71.727997 | AB13: =AB6*$AJ$4/$AI$4 -> 8.9889306 | AC13: =AC6*$AJ$4/$AI$4 -> 10.823406 | ... AF13: =AF6*$AJ$4/$AI$4 -> 3.8523988 | AH13: 41 | AI13: =SUM(V13:AH13) -> 707.18982
V14: =V7*$AJ$4/$AI$4 -> 82.184508 | W14: =W7*$AJ$4/$AI$4 -> 84.752774 | X14: =X7*$AJ$4/$AI$4 -> 132.44914 | Y14: =Y7*$AJ$4/$AI$4 -> 107.592 | Z14: =Z7*$AJ$4/$AI$4 -> 146.9415 | AA14: =AA7*$AJ$4/$AI$4 -> 71.452826 | AB14: =AB7*$AJ$4/$AI$4 -> 8.9889306 | AC14: =AC7*$AJ$4/$AI$4 -> 7.0627312 | ... AF14: =AF7*$AJ$4/$AI$4 -> 3.8523988 | AH14: 33 | AI14: =SUM(V14:AH14) -> 683.50506
V15: =V8*$AJ$4/$AI$4 -> 146.11598 | W15: =W8*$AJ$4/$AI$4 -> 85.39484 | X15: =X8*$AJ$4/$AI$4 -> 100.98788 | Y15: =Y8*$AJ$4/$AI$4 -> 95.209285 | Z15: =Z8*$AJ$4/$AI$4 -> 118.4154 | AA15: =AA8*$AJ$4/$AI$4 -> 70.535588 | AB15: =AB8*$AJ$4/$AI$4 -> 8.9889306 | AC15: =AC8*$AJ$4/$AI$4 -> 0.18344756 | ... AF15: =AF8*$AJ$4/$AI$4 -> 3.760675 | AH15: 28 | AI15: =SUM(V15:AH15) -> 659.33479
V16: =V9*$AJ$4/$AI$4 -> 173.63312 | W16: =W9*$AJ$4/$AI$4 -> 136.85188 | X16: =X9*$AJ$4/$AI$4 -> 78.60728 | Y16: =Y9*$AJ$4/$AI$4 -> 79.524518 | Z16: =Z9*$AJ$4/$AI$4 -> 71.452826 | AA16: =AA9*$AJ$4/$AI$4 -> 68.976283 | AB16: =AB9*$AJ$4/$AI$4 -> 8.9889306 | AC16: =AC9*$AJ$4/$AI$4 -> 0 | ... AF16: =AF9*$AJ$4/$AI$4 -> 3.3020561 | AH16: 26 | AI16: =SUM(V16:AH16) -> 647.33689
U18: M0 | V18: =V11*100/$AI$11 -> 0 | W18: =W11*100/$AI$11 -> 0 | X18: =X11*100/$AI$11 -> 30.784257 | Y18: =Y11*100/$AI$11 -> 18.059291 | Z18: =Z11*100/$AI$11 -> 27.034505 | AA18: =AA11*100/$AI$11 -> 9.6525883 | AB18: =AB11*100/$AI$11 -> 1.1854056 | AC18: =AC11*100/$AI$11 -> 3.3263932 | ... AH18: =AH11*100/$AI$11 -> 6.4618225 | AI18: =SUM(V18:AH18) -> 100 | AK18: day | AL18: 365
K19: to be build | L19: 0 | N19: =132+90 -> 222 | O19: 83 | P19: =26+39 -> 65 | Q19: 4 | U19: M1 | V19: =V12*100/$AI$12 -> 0 | W19: =W12*100/$AI$12 -> 11.322079 | X19: =X12*100/$AI$12 -> 31.81916 | Y19: =Y12*100/$AI$12 -> 14.817318 | Z19: =Z12*100/$AI$12 -> 20.272388 | AA19: =AA12*100/$AI$12 -> 9.9239829 | AB19: =AB12*100/$AI$12 -> 1.2233337 | AC19: =AC12*100/$AI$12 -> 2.7088104 | ... AH19: =AH12*100/$AI$12 -> 5.715921 | AI19: =SUM(V19:AH19) -> 100 | AK19: hour | AL19: 24
L20: 0 | N20: =114+114 -> 228 | O20: 68 | P20: =19+28 -> 47 | Q20: 4 | U20: M23 | V20: =V13*100/$AI$13 -> 0 | W20: =W13*100/$AI$13 -> 11.815832 | X20: =X13*100/$AI$13 -> 19.844373 | Y20: =Y13*100/$AI$13 -> 18.845669 | Z20: =Z13*100/$AI$13 -> 27.924794 | AA20: =AA13*100/$AI$13 -> 10.142679 | AB20: =AB13*100/$AI$13 -> 1.2710775 | AC20: =AC13*100/$AI$13 -> 1.530481 | ... AH20: =AH13*100/$AI$13 -> 5.7975947 | AI20: =SUM(V20:AH20) -> 100 | AK20: efficiency | AL20: 2050 | AO20: 2021 | AQ20: solar efficiency
L21: 0 | N21: =89+49 -> 138 | O21: 81 | P21: =25+38 -> 63 | Q21: 4 | U21: N1 | V21: =V14*100/$AI$14 -> 12.02398 | W21: =W14*100/$AI$14 -> 12.399729 | X21: =X14*100/$AI$14 -> 19.377931 | Y21: =Y14*100/$AI$14 -> 15.741214 | Z21: =Z14*100/$AI$14 -> 21.498231 | AA21: =AA14*100/$AI$14 -> 10.453884 | AB21: =AB14*100/$AI$14 -> 1.3151228 | AC21: =AC14*100/$AI$14 -> 1.0333107 | ... AH21: =AH14*100/$AI$14 -> 4.828055 | AI21: =SUM(V21:AH21) -> 100 | AK21: EN | AL21: 0.7 | AN21: = | AO21: 0.7 | AQ21: 208 | AR21: =X4/(AQ21*$AL$18*$AL$19*0.001) -> 0.13967554
L22: 13 | N22: =86+46 -> 132 | O22: 67 | P22: =19+28 -> 47 | Q22: 4 | U22: N2 | V22: =V15*100/$AI$15 -> 22.161122 | W22: =W15*100/$AI$15 -> 12.951666 | X22: =X15*100/$AI$15 -> 15.316632 | Y22: =Y15*100/$AI$15 -> 14.440204 | Z22: =Z15*100/$AI$15 -> 17.959829 | AA22: =AA15*100/$AI$15 -> 10.697993 | AB22: =AB15*100/$AI$15 -> 1.3633333 | AC22: =AC15*100/$AI$15 -> 0.027823128 | ... AH22: =AH15*100/$AI$15 -> 4.2467045 | AI22: =SUM(V22:AH22) -> 100 | AK22: NN | AL22: 0.78 | AM22: 0.855 | AQ22: 214 | AR22: =X5/(AQ22*$AL$18*$AL$19*0.001) -> 0.13597277
L23: 23 | N23: =61+43 -> 104 | O23: 61 | P23: =16+23 -> 39 | Q23: 4 | U23: N03 | V23: =V16*100/$AI$16 -> 26.822682 | W23: =W16*100/$AI$16 -> 21.140751 | X23: =X16*100/$AI$16 -> 12.143179 | Y23: =Y16*100/$AI$16 -> 12.284873 | Z23: =Z16*100/$AI$16 -> 11.037966 | AA23: =AA16*100/$AI$16 -> 10.655392 | AB23: =AB16*100/$AI$16 -> 1.3886016 | AC23: =AC16*100/$AI$16 -> 0 | ... AH23: =AH16*100/$AI$16 -> 4.0164558 | AI23: =SUM(V23:AH23) -> 100 | AK23: S | AL23: 0.1395 | AN23: < | AO23: 0.17 | AQ23: 125 | AR23: =X6/(AQ23*$AL$18*$AL$19*0.001) -> 0.13972603
L24: 23 | N24: =49+35 -> 84 | O24: 52 | P24: =11+14 -> 25 | Q24: 4 | AK24: LW | AL24: 0.23 | AN24: </= | AO24: 0.25 | AQ24: 118 | AR24: =X7/(AQ24*$AL$18*$AL$19*0.001) -> 0.13969507
K25: Existant | N25: 14.6 | O25: 20.8 | Q25: 25.5 | V25: to produce 1kWh: | AI25: ass rest | AK25: SW | AL25: 0.412 | AQ25: 90 | AR25: =X8/(AQ25*$AL$18*$AL$19*0.001) -> 0.13964992
N26: =N19-N25 -> 207.4 | O26: =O19-O25 -> 62.2 | P26: 65 | U26: M0 | V26: =V11/$AI$11 -> 0 | W26: =W11/$AI$11 -> 0 | X26: =X11/$AI$11 -> 0.30784257 | Y26: =Y11/$AI$11 -> 0.18059291 | Z26: =Z11/$AI$11 -> 0.27034505 | AA26: =AA11/$AI$11 -> 0.096525883 | AB26: =AB11/$AI$11 -> 0.011854056 | AC26: =AC11/$AI$11 -> 0.033263932 | ... AH26: =AH11/$AI$11 -> 0.064618225 | AI26: =SUM(AC26:AF26) -> 0.068221301 | AJ26: =SUM(V26:AB26)+AH26+AI26 -> 1 | AK26: H | AL26: 0.41 | AQ26: 70 | AR26: =X9/(AQ26*$AL$18*$AL$19*0.001) -> 0.13975864
U27: M1 | V27: =V12/$AI$12 -> 0 | W27: =W12/$AI$12 -> 0.11322079 | X27: =X12/$AI$12 -> 0.3181916 | Y27: =Y12/$AI$12 -> 0.14817318 | Z27: =Z12/$AI$12 -> 0.20272388 | AA27: =AA12/$AI$12 -> 0.099239829 | AB27: =AB12/$AI$12 -> 0.012233337 | AC27: =AC12/$AI$12 -> 0.027088104 | ... AH27: =AH12/$AI$12 -> 0.05715921 | AI27: =SUM(AC27:AF27) -> 0.04905818 | AJ27: =SUM(V27:AB27)+AH27+AI27 -> 1 | AR27: =AVERAGE(AR21:AR26) -> 0.13907966
O28: electricity | Q28: sulfur | U28: M23 | V28: =V13/$AI$13 -> 0 | W28: =W13/$AI$13 -> 0.11815832 | X28: =X13/$AI$13 -> 0.19844373 | Y28: =Y13/$AI$13 -> 0.18845669 | Z28: =Z13/$AI$13 -> 0.27924794 | AA28: =AA13/$AI$13 -> 0.10142679 | AB28: =AB13/$AI$13 -> 0.012710775 | AC28: =AC13/$AI$13 -> 0.01530481 | ... AH28: =AH13/$AI$13 -> 0.057975947 | AI28: =SUM(AC28:AF28) -> 0.043579799 | AJ28: =SUM(V28:AB28)+AH28+AI28 -> 1 | AK28: 5.6546355e-09 | AL28: =AK28*$AL$34 -> 8.1217118e-09 | AM28: kilometer | AN28: transmission network, electricity, high voltage direct current aerial line
L29: High-medium | M29: 1.0067044 | N29: 0.99895194 | O29: =M29*N29 -> 1.0056493 | Q29: 5.4e-08 | U29: N1 | V29: =V14/$AI$14 -> 0.1202398 | W29: =W14/$AI$14 -> 0.12399729 | X29: =X14/$AI$14 -> 0.19377931 | Y29: =Y14/$AI$14 -> 0.15741214 | Z29: =Z14/$AI$14 -> 0.21498231 | AA29: =AA14/$AI$14 -> 0.10453884 | AB29: =AB14/$AI$14 -> 0.013151228 | AC29: =AC14/$AI$14 -> 0.010333107 | ... AH29: =AH14/$AI$14 -> 0.04828055 | AI29: =SUM(AC29:AF29) -> 0.023618531 | AJ29: =SUM(V29:AB29)+AH29+AI29 -> 1 | AK29: 3.8616897e-10 | AL29: =AK29*$AL$34 -> 5.5465169e-10 | AM29: kilometer | AN29: transmission network, electricity, high voltage direct current land cable
L30: 0.0042098906 | O30: =O29*L30 -> 0.0042336737 | U30: N2 | V30: =V15/$AI$15 -> 0.22161122 | W30: =W15/$AI$15 -> 0.12951666 | X30: =X15/$AI$15 -> 0.15316632 | Y30: =Y15/$AI$15 -> 0.14440204 | Z30: =Z15/$AI$15 -> 0.17959829 | AA30: =AA15/$AI$15 -> 0.10697993 | AB30: =AB15/$AI$15 -> 0.013633333 | AC30: =AC15/$AI$15 -> 0.00027823128 | ... AH30: =AH15/$AI$15 -> 0.042467045 | AI30: =SUM(AC30:AF30) -> 0.0086251697 | AJ30: =SUM(V30:AB30)+AH30+AI30 -> 1 | AK30: 3.4744698e-12 | AL30: =AK30*$AL$34 -> 4.9903556e-12 | AM30: kilometer | AN30: transmission network, electricity, high voltage direct current subsea cable
O31: =O29+O30 -> 1.009883 | U31: N03 | V31: =V16/$AI$16 -> 0.26822682 | W31: =W16/$AI$16 -> 0.21140751 | X31: =X16/$AI$16 -> 0.12143179 | Y31: =Y16/$AI$16 -> 0.12284873 | Z31: =Z16/$AI$16 -> 0.11037966 | AA31: =AA16/$AI$16 -> 0.10655392 | AB31: =AB16/$AI$16 -> 0.013886016 | AC31: =AC16/$AI$16 -> 0 | ... AH31: =AH16/$AI$16 -> 0.040164558 | AI31: =SUM(AC31:AF31) -> 0.0051009855 | AJ31: =SUM(V31:AB31)+AH31+AI31 -> 1 | AK31: 1.8627768e-08 | AL31: =AK31*$AL$34 -> 2.6754927e-08 | AM31: kilometer | AN31: market for transmission network, electricity, medium voltage
AK32: 8.7404881e-08 | AL32: =AK32*$AL$34 -> 1.2553899e-07 | AM32: kilometer | AN32: market for distribution network, electricity, low voltage
L33: medium-low | M33: 1.0309366 | N33: 0.9590095 | O33: =M33*N33 -> 0.98867799 | Q33: 4.03e-10 | V33: from premise:
L34: 0.030698134 | O34: =O33*L34 -> 0.030350569 | AJ34: demand 2050 | AK34: 773.3 | AL34: =AK34/AK35 -> 1.4362927 | AM34: demand increase
O35: =O33+O34 -> 1.0190286 | AJ35: demand 2019 | AK35: 538.4
U36: M0 | V36: 0 | W36: 0 | X36: 0.32202961 | Y36: 0.1889156 | Z36: 0.282804 | AA36: =AA39+AA40 -> 0.10097431 | AB36: =AB39+AB40 -> 0.013033025 | AC36: 0.034796913 | AD36: 0.011008478 | AE36: 0.020245476 | AF36: =AF40+AF41+AF42 -> 0.026192585 | AI36: 6.58e-09
K37: H-H | L37: 0.031242685 | X37: electricity production, photovoltaic | Y37: electricity production, wind, 1-3MW turbine, onshore | Z37: electricity production, wind, 1-3MW turbine, offshore | AA37: electricity production, hydro, reservoir, alpine region | AB37: electricity production, natural gas, combined cycle power plant | AC37: electricity production, from stationary battery, FE2050 | AD37: electricity production, wave energy converter | AE37: electricity production, from hydrogen, FE2050 | AF37: electricity production, from vehicle-to-grid, FE2050 | AI37: transmission network construction, electricity, high voltage
K38: H-M | L38: 1.0067044 | AA38: electricity production, hydro, run-of-river | AB38: heat and power co-generation, wood chips, 6667 kW | AF38: electricity production, hydro, pumped storage
K39: M-M | L39: 0.0042098906 | AA39: 0.025243578 | AB39: 0.00063267114 | AF39: treatment of municipal solid waste, incineration
K40: M-L | L40: 1.0309366 | AA40: 0.075730735 | AB40: 0.012400354 | AF40: 0.0024041503
K41: L-L | L41: 0.030698134 | AF41: 0.021510819
AF42: 0.0022776161

Sheet Nuclear
A1: skip
E2: EN | G2: NN
E3: =Sheet1!W26 -> 0 | F3: M0 | G3: =Sheet1!V26 -> 0
E4: =Sheet1!W27 -> 0.11322079 | F4: M1 | G4: =Sheet1!V27 -> 0
E5: =Sheet1!W28 -> 0.11815832 | F5: M23 | G5: =Sheet1!V28 -> 0
E6: =Sheet1!W29 -> 0.12399729 | F6: N1 | G6: =Sheet1!V29 -> 0.1202398
E7: =Sheet1!W30 -> 0.12951666 | F7: N2 | G7: =Sheet1!V30 -> 0.22161122
E8: =Sheet1!W31 -> 0.21140751 | F8: N03 | G8: =Sheet1!V31 -> 0.26822682
B12: Electricity, High Voltage | C12: electricity production, nuclear, pressure water reactor - FR | D12: 0.71316

Sheet Solar
A1: skip
D3: =Sheet1!X26 -> 0.30784257 | E3: M0
D4: =Sheet1!X27 -> 0.3181916 | E4: M1
D5: =Sheet1!X28 -> 0.19844373 | E5: M23
D6: =Sheet1!X29 -> 0.19377931 | E6: N1
D7: =Sheet1!X30 -> 0.15316632 | E7: N2
D8: =Sheet1!X31 -> 0.12143179 | E8: N03 | I8: Percentage multi/single
I9: =H11+H12 -> 0.12480104
D10: current inputs | F10: future %M0 | H10: future input M0 | K10: future %M1 | M10: future input M1 | P10: future %M23 | R10: future input M23 | U10: future %N1 | W10: future input M23 | Z10: future %N2 | AB10: future input M23 | AE10: future %N03 | AG10: future input M23
B11: Electricity, Low Voltage | C11: electricity production, photovoltaic, 3kWp slanted-roof installation, multi-Si, panel, mounted - FR | D11: 0.014308 | F11: =G17*$G$25/100 -> 22.472263 | G11: 22 | H11: =F11*$D$3/100 -> 0.069179193 | I11: =H11*100/I9 -> 55.431582 | K11: =L17*$G$25/100 -> 27.715791 | L11: 22 | M11: =K11*$D$4/100 -> 0.08818932 | P11: =Q17*$G$25/100 -> 19.682228 | Q11: 22 | R11: =P11*$D$5/100 -> 0.039058148 | U11: =V17*$G$25/100 -> 19.317067 | V11: 22 | W11: =U11*$D$6/100 -> 0.037432479 | Z11: =AA17*$G$25/100 -> 22.918827 | AA11: 22 | AB11: =Z11*$D$7/100 -> 0.035103924 | AE11: =AF17*$G$25/100 -> 23.096493 | AF11: 22 | AG11: =AE11*$D$8/100 -> 0.028046485
B12: Electricity, Low Voltage | C12: electricity production, photovoltaic, 3kWp slanted-roof installation, single-Si, panel, mounted - FR | D12: 0.011504 | F12: =G17*$G$26/100 -> 18.068277 | G12: 18 | H12: =F12*$D$3/100 -> 0.05562185 | I12: =H12*100/I9 -> 44.568418 | K12: =L17*$G$26/100 -> 22.284209 | L12: 18 | M12: =K12*$D$4/100 -> 0.070906481 | P12: =Q17*$G$26/100 -> 15.825018 | Q12: 18 | R12: =P12*$D$5/100 -> 0.031403756 | U12: =V17*$G$26/100 -> 15.531418 | V12: 18 | W12: =U12*$D$6/100 -> 0.030096676 | Z12: =AA17*$G$26/100 -> 18.427327 | AA12: 18 | AB12: =Z12*$D$7/100 -> 0.028224458 | AE12: =AF17*$G$26/100 -> 18.570174 | AF12: 18 | AG12: =AE12*$D$8/100 -> 0.022550096
B13: Electricity, Low Voltage | C13: electricity production, photovoltaic, 570kWp open ground installation, multi-Si - FR | D13: 0.0089283 | F13: =$G$18 -> 59.459459 | G13: 60 | H13: =F13*$D$3/100 -> 0.18304153 | K13: =L18 -> 50 | L13: 60 | M13: =K13*$D$4/100 -> 0.1590958 | P13: =Q18 -> 64.492754 | Q13: 60 | R13: =P13*$D$5/100 -> 0.12798182 | U13: =V18 -> 65.151515 | V13: 60 | W13: =U13*$D$6/100 -> 0.12625016 | Z13: =AA18 -> 58.653846 | AA13: 60 | AB13: =Z13*$D$7/100 -> 0.089837938 | AE13: =AF18 -> 58.333333 | AF13: 60 | AG13: =AE13*$D$8/100 -> 0.070835213
B14: T | D14: =SUM(D11:D13) -> 0.0347403 | H14: =SUM(H11:H13) -> 0.30784257 | M14: =SUM(M11:M13) -> 0.3181916 | R14: =SUM(R11:R13) -> 0.19844373 | W14: =SUM(W11:W13) -> 0.19377931 | AB14: =SUM(AB11:AB13) -> 0.15316632 | AG14: =SUM(AG11:AG13) -> 0.12143179
F15: % | G15: % | K15: % | L15: % | P15: % | Q15: % | U15: % | V15: % | Z15: % | AA15: % | AE15: % | AF15: %
E17: roof | F17: 90 | G17: =F17*100/222 -> 40.540541 | J17: roof | K17: 114 | L17: =K17*100/228 -> 50 | O17: roof | P17: 49 | Q17: =P17*100/138 -> 35.507246 | T17: roof | U17: 46 | V17: =U17*100/132 -> 34.848485 | Y17: roof | Z17: 43 | AA17: =Z17*100/104 -> 41.346154 | AD17: roof | AE17: 35 | AF17: =AE17*100/84 -> 41.666667
B18: T | E18: groung | F18: 132 | G18: =F18*100/222 -> 59.459459 | J18: groung | K18: 114 | L18: =K18*100/228 -> 50 | O18: groung | P18: 89 | Q18: =P18*100/138 -> 64.492754 | T18: groung | U18: 86 | V18: =U18*100/132 -> 65.151515 | Y18: groung | Z18: 61 | AA18: =Z18*100/104 -> 58.653846 | AD18: groung | AE18: 49 | AF18: =AE18*100/84 -> 58.333333
E19: total | F19: =F17+F18 -> 222 | J19: total | K19: =K17+K18 -> 228 | O19: total | P19: =P17+P18 -> 138 | T19: total | U19: =U17+U18 -> 132 | Y19: total | Z19: =Z17+Z18 -> 104 | AD19: total | AE19: =AE17+AE18 -> 84
E21: RTE M0 | F21: =Sheet1!N4 -> 208 | J21: RTE M1 | K21: =Sheet1!N5 -> 214 | O21: RTE M23 | P21: =Sheet1!N6 -> 125 | T21: RTE M23 | U21: =Sheet1!N7 -> 118 | Y21: RTE M23 | Z21: =Sheet1!N8 -> 90 | AD21: RTE M23 | AE21: =Sheet1!N9 -> 70
D22: I dont know what is the existant proportion of roof and ground solar pannel to be replaced… | E22: Existant | F22: 14.6 | G22: entsoe | J22: Existant | K22: 14.6 | L22: entsoe | O22: Existant | P22: 14.6 | Q22: entsoe | T22: Existant | U22: 14.6 | V22: entsoe | Y22: Existant | Z22: 14.6 | AA22: entsoe | AD22: Existant | AE22: 14.6 | AF22: entsoe
E23: total | F23: =F21+F22 -> 222.6 | J23: total | K23: =K21+K22 -> 228.6 | O23: total | P23: =P21+P22 -> 139.6 | T23: total | U23: =U21+U22 -> 132.6 | Y23: total | Z23: =Z21+Z22 -> 104.6 | AD23: total | AE23: =AE21+AE22 -> 84.6
E25: roof m | F25: 0.014308 | G25: =F25*100/F27 -> 55.431582
E26: roof s | F26: 0.011504 | G26: =F26*100/F27 -> 44.568418
E27: total | F27: 0.025812
B29: premise 17/83 residential/commercial | I29: =H31+H32 -> 0.12480104
D30: current inputs | F30: future %M0 | H30: future input M0 | K30: future %M1 | M30: future input M1 | P30: future %M23 | R30: future input M23 | U30: future %N1 | W30: future input M23 | Z30: future %N2 | AB30: future input M23 | AE30: future %N03 | AG30: future input M23
B31: Electricity, Low Voltage | C31: electricity production, photovoltaic, 3kWp slanted-roof installation, multi-Si, panel, mounted - FR | D31: 0.014308 | F31: =G37*$G$45/100 -> 33.648649 | G31: 22 | H31: =F31*$D$3/100 -> 0.10358487 | I31: =H31*100/I29 -> 83 | K31: =L37*$G$45/100 -> 41.5 | L31: 22 | M31: =K31*$D$4/100 -> 0.13204952 | P31: =Q37*$G$45/100 -> 29.471014 | Q31: 22 | R31: =P31*$D$5/100 -> 0.05848338 | U31: =V37*$G$45/100 -> 28.924242 | V31: 22 | W31: =U31*$D$6/100 -> 0.056049198 | Z31: =AA37*$G$45/100 -> 34.317308 | AA31: 22 | AB31: =Z31*$D$7/100 -> 0.052562557 | AE31: =AF37*$G$45/100 -> 34.583333 | AF31: 22 | AG31: =AE31*$D$8/100 -> 0.041995162
B32: Electricity, Low Voltage | C32: electricity production, photovoltaic, 3kWp slanted-roof installation, single-Si, panel, mounted - FR | D32: 0.011504 | F32: =G37*$G$46/100 -> 6.8918919 | G32: 18 | H32: =F32*$D$3/100 -> 0.021216177 | I32: =H32*100/I29 -> 17 | K32: =L37*$G$46/100 -> 8.5 | L32: 18 | M32: =K32*$D$4/100 -> 0.027046286 | P32: =Q37*$G$46/100 -> 6.0362319 | Q32: 18 | R32: =P32*$D$5/100 -> 0.011978524 | U32: =V37*$G$46/100 -> 5.9242424 | V32: 18 | W32: =U32*$D$6/100 -> 0.011479956 | Z32: =AA37*$G$46/100 -> 7.0288462 | AA32: 18 | AB32: =Z32*$D$7/100 -> 0.010765825 | AE32: =AF37*$G$46/100 -> 7.0833333 | AF32: 18 | AG32: =AE32*$D$8/100 -> 0.0086014188
B33: Electricity, Low Voltage | C33: electricity production, photovoltaic, 570kWp open ground installation, multi-Si - FR | D33: 0.0089283 | F33: =$G$18 -> 59.459459 | G33: 60 | H33: =F33*$D$3/100 -> 0.18304153 | K33: =L38 -> 50 | L33: 60 | M33: =K33*$D$4/100 -> 0.1590958 | P33: =Q38 -> 64.492754 | Q33: 60 | R33: =P33*$D$5/100 -> 0.12798182 | U33: =V38 -> 65.151515 | V33: 60 | W33: =U33*$D$6/100 -> 0.12625016 | Z33: =AA38 -> 58.653846 | AA33: 60 | AB33: =Z33*$D$7/100 -> 0.089837938 | AE33: =AF38 -> 58.333333 | AF33: 60 | AG33: =AE33*$D$8/100 -> 0.070835213
B34: T | D34: =SUM(D31:D33) -> 0.0347403 | H34: =SUM(H31:H33) -> 0.30784257 | M34: =SUM(M31:M33) -> 0.3181916 | R34: =SUM(R31:R33) -> 0.19844373 | W34: =SUM(W31:W33) -> 0.19377931 | AB34: =SUM(AB31:AB33) -> 0.15316632 | AG34: =SUM(AG31:AG33) -> 0.12143179
F35: % | G35: % | K35: % | L35: % | P35: % | Q35: % | U35: % | V35: % | Z35: % | AA35: % | AE35: % | AF35: %
E37: roof | F37: 90 | G37: =F37*100/222 -> 40.540541 | J37: roof | K37: 114 | L37: =K37*100/228 -> 50 | O37: roof | P37: 49 | Q37: =P37*100/138 -> 35.507246 | T37: roof | U37: 46 | V37: =U37*100/132 -> 34.848485 | Y37: roof | Z37: 43 | AA37: =Z37*100/104 -> 41.346154 | AD37: roof | AE37: 35 | AF37: =AE37*100/84 -> 41.666667
B38: T | E38: groung | F38: 132 | G38: =F38*100/222 -> 59.459459 | J38: groung | K38: 114 | L38: =K38*100/228 -> 50 | O38: groung | P38: 89 | Q38: =P38*100/138 -> 64.492754 | T38: groung | U38: 86 | V38: =U38*100/132 -> 65.151515 | Y38: groung | Z38: 61 | AA38: =Z38*100/104 -> 58.653846 | AD38: groung | AE38: 49 | AF38: =AE38*100/84 -> 58.333333
E39: total | F39: =F37+F38 -> 222 | J39: total | K39: =K37+K38 -> 228 | O39: total | P39: =P37+P38 -> 138 | T39: total | U39: =U37+U38 -> 132 | Y39: total | Z39: =Z37+Z38 -> 104 | AD39: total | AE39: =AE37+AE38 -> 84
E41: RTE M0 | F41: =Sheet1!N31 -> 0 | J41: RTE M1 | K41: =Sheet1!N33 -> 0.9590095 | O41: RTE M23 | P41: =Sheet1!N34 -> 0 | T41: RTE M23 | U41: =Sheet1!N35 -> 0 | Y41: RTE M23 | Z41: =Sheet1!N36 -> 0 | AD41: RTE M23 | AE41: =Sheet1!N37 -> 0
E42: Existant | F42: 14.6 | G42: entsoe | J42: Existant | K42: 14.6 | L42: entsoe | O42: Existant | P42: 14.6 | Q42: entsoe | T42: Existant | U42: 14.6 | V42: entsoe | Y42: Existant | Z42: 14.6 | AA42: entsoe | AD42: Existant | AE42: 14.6 | AF42: entsoe
E43: total | F43: =F41+F42 -> 14.6 | J43: total | K43: =K41+K42 -> 15.55901 | O43: total | P43: =P41+P42 -> 14.6 | T43: total | U43: =U41+U42 -> 14.6 | Y43: total | Z43: =Z41+Z42 -> 14.6 | AD43: total | AE43: =AE41+AE42 -> 14.6
E45: roof m | F45: 0.014308 | G45: 83
E46: roof s | F46: 0.011504 | G46: 17
E47: total | F47: 0.025812

Sheet Biogas
A1: skip
D5: EI | F5: new
B6: Electricity, High Voltage | C6: heat and power co-generation, biogas, gas engine - FR | D6: 0.0016317 | E6: M0 | F6: =Sheet1!AB26 -> 0.011854056
E7: M1 | F7: =Sheet1!AB27 -> 0.012233337
E8: M23 | F8: =Sheet1!AB28 -> 0.012710775
E9: N1 | F9: =Sheet1!AB29 -> 0.013151228
E10: N2 | F10: =Sheet1!AB30 -> 0.013633333
E11: N03 | F11: =Sheet1!AB31 -> 0.013886016

Sheet hydro
A1: skip
D3: =Sheet1!AA26 -> 0.096525883 | E3: M0
D4: =Sheet1!AA27 -> 0.099239829 | E4: M1
D5: =Sheet1!AA28 -> 0.10142679 | E5: M23
D6: =Sheet1!AA29 -> 0.10453884 | E6: N1
D7: =Sheet1!AA30 -> 0.10697993 | E7: N2
D8: =Sheet1!AA31 -> 0.10655392 | E8: N03
G12: M0 | H12: M1 | I12: M23 | J12: N1 | K12: N2 | L12: N03
B13: Electricity, High Voltage | C13: electricity production, hydro, reservoir, alpine region - FR | D13: 0.016962 | E13: =D13*100/D15 -> 15.999623 | G13: =E13*D3/100 -> 0.015443777 | H13: =E13*D4/100 -> 0.015877998 | I13: =E13*D5/100 -> 0.016227904 | J13: =E13*D6/100 -> 0.01672582 | K13: =E13*D7/100 -> 0.017116385 | L13: =E13*D8/100 -> 0.017048225
B14: Electricity, High Voltage | C14: electricity production, hydro, run-of-river - FR | D14: 0.089053 | E14: =D14*100/D15 -> 84.000377 | G14: =E14*D3/100 -> 0.081082106 | H14: =E14*D4/100 -> 0.083361831 | I14: =E14*D5/100 -> 0.08519889 | J14: =E14*D6/100 -> 0.08781302 | K14: =E14*D7/100 -> 0.089863543 | L14: =E14*D8/100 -> 0.089505695
D15: =SUM(D13:D14) -> 0.106015
B16: T

Sheet Wind
A1: skip
D2: onshore | F2: offshore
D3: =Sheet1!Y26 -> 0.18059291 | E3: M0 | F3: =Sheet1!Z26 -> 0.27034505
D4: =Sheet1!Y27 -> 0.14817318 | E4: M1 | F4: =Sheet1!Z27 -> 0.20272388
D5: =Sheet1!Y28 -> 0.18845669 | E5: M23 | F5: =Sheet1!Z28 -> 0.27924794
D6: =Sheet1!Y29 -> 0.15741214 | E6: N1 | F6: =Sheet1!Z29 -> 0.21498231
D7: =Sheet1!Y30 -> 0.14440204 | E7: N2 | F7: =Sheet1!Z30 -> 0.17959829
D8: =Sheet1!Y31 -> 0.12284873 | E8: N03 | F8: =Sheet1!Z31 -> 0.11037966
D12: EI | G12: M0 | H12: M1 | I12: M23 | J12: N1 | K12: N2 | L12: N03
B13: Electricity, High Voltage | C13: electricity production, wind, 1-3MW turbine, onshore - FR | D13: 0.058909 | E13: =D13*100/$D$16 -> 93.597927 | G13: =$D$3*E13/100 -> 0.16903122 | H13: =$D$4*E13/100 -> 0.13868702 | I13: =$D$5*E13/100 -> 0.17639156 | J13: =$D$6*E13/100 -> 0.1473345 | K13: =$D$7*E13/100 -> 0.13515731 | L13: =$D$8*E13/100 -> 0.11498387
A14: T | B14: Electricity, High Voltage | C14: electricity production, wind, <1MW turbine, onshore - FR | D14: 0.003786 | E14: =D14*100/$D$16 -> 6.0154094 | G14: =$D$3*E14/100 -> 0.010863403 | H14: =$D$4*E14/100 -> 0.0089132233 | I14: =$D$5*E14/100 -> 0.011336441 | J14: =$D$6*E14/100 -> 0.0094689848 | K14: =$D$7*E14/100 -> 0.0086863735 | L14: =$D$8*E14/100 -> 0.0073898543
B15: Electricity, High Voltage | C15: electricity production, wind, >3MW turbine, onshore - FR | D15: 0.00024336 | E15: =D15*100/$D$16 -> 0.38666403 | G15: =$D$3*E15/100 -> 0.00069828783 | H15: =$D$4*E15/100 -> 0.00057293239 | I15: =$D$5*E15/100 -> 0.00072869424 | J15: =$D$6*E15/100 -> 0.00060865614 | K15: =$D$7*E15/100 -> 0.00055835073 | L15: =$D$8*E15/100 -> 0.00047501187
D16: =D13+D14+D15 -> 0.06293836 | G16: =SUM(G13:G15) -> 0.18059291 | H16: =SUM(H13:H15) -> 0.14817318 | I16: =SUM(I13:I15) -> 0.18845669 | J16: =SUM(J13:J15) -> 0.15741214 | K16: =SUM(K13:K15) -> 0.14440204 | L16: =SUM(L13:L15) -> 0.12284873
E17: scenario | F17: 74
A18: T | E18: existant onshore | F18: 20.8
B21: Electricity, High Voltage | C21: electricity production, wind, 1-3MW turbine, offshore - FR | D21: 3.5906e-05 | G21: 26 | H21: 19 | I21: 25 | J21: 19 | K21: 16 | L21: 11
B22: Electricity, High Voltage | C22: electricity production, wind, 1-3MW turbine, offshore Flotant- FR | G22: 39 | H22: 28 | I22: 38 | J22: 28 | K22: 23 | L22: 14
G23: =SUM(G21:G22) -> 65 | H23: =SUM(H21:H22) -> 47 | I23: =SUM(I21:I22) -> 63 | J23: =SUM(J21:J22) -> 47 | K23: =SUM(K21:K22) -> 39 | L23: =SUM(L21:L22) -> 25
F24: % | G24: =G21*100/G23 -> 40 | H24: =H21*100/H23 -> 40.425532 | I24: =I21*100/I23 -> 39.68254 | J24: =J21*100/J23 -> 40.425532 | K24: =K21*100/K23 -> 41.025641 | L24: =L21*100/L23 -> 44
F25: % | G25: =G22*100/G23 -> 60 | H25: =H22*100/H23 -> 59.574468 | I25: =I22*100/I23 -> 60.31746 | J25: =J22*100/J23 -> 59.574468 | K25: =K22*100/K23 -> 58.974359 | L25: =L22*100/L23 -> 56
F26: fixed | G26: =F3*G24/100 -> 0.10813802 | H26: =F4*H24/100 -> 0.081952206 | I26: =F5*I24/100 -> 0.11081267 | J26: =F6*J24/100 -> 0.086907743 | K26: =F7*K24/100 -> 0.073681351 | L26: =F8*L24/100 -> 0.04856705
F27: float | G27: =F3*G25/100 -> 0.16220703 | H27: =F4*H25/100 -> 0.12077167 | I27: =F5*I25/100 -> 0.16843527 | J27: =F6*J25/100 -> 0.12807457 | K27: =F7*K25/100 -> 0.10591694 | L27: =F8*L25/100 -> 0.061812609
B29: T | C29: electricity production, wind, 1-3MW turbine, onshore - FR | D29: 0.18070827
C30: electricity production, wind, <1MW turbine, onshore - FR | D30: 0.011613871
C31: electricity production, wind, >3MW turbine, onshore - FR | D31: 0.00074652709
C32: electricity production, wind, 1-3MW turbine, offshore - FR | D32: 0.11560843
C33: electricity production, wind, 1-3MW turbine, offshore Flotant- FR | D33: 0.17341265

Sheet imports
A1: skip | N1: 0.9
G2: IT | H2: GB | I2: DE | J2: CH | K2: BE | L2: ES | N2: IT | O2: GB | P2: DE | Q2: CH | R2: BE | S2: ES
D3: M0 | E3: =Sheet1!AH26 -> 0.064618225 | G3: =E3*$E$10 -> 0.0039099281 | H3: =E3*$E$11 -> 0.0029299327 | I3: =E3*$E$12 -> 0.010202485 | J3: =E3*$E$13 -> 0.018938387 | K3: =E3*$E$14 -> 0.015800922 | L3: =E3*$E$15 -> 0.012836571 | N3: =G3*$N$1 -> 0.0035189353 | O3: =H3*$N$1 -> 0.0026369395 | P3: =I3*$N$1 -> 0.0091822362 | Q3: =J3*$N$1 -> 0.017044548 | R3: =K3*$N$1 -> 0.014220829 | S3: =L3*$N$1 -> 0.011552914
D4: M1 | E4: =Sheet1!AH27 -> 0.05715921 | G4: =E4*$E$10 -> 0.0034585971 | H4: =E4*$E$11 -> 0.0025917246 | I4: =E4*$E$12 -> 0.0090247909 | J4: =E4*$E$13 -> 0.01675229 | K4: =E4*$E$14 -> 0.013976989 | L4: =E4*$E$15 -> 0.011354819 | N4: =G4*$N$1 -> 0.0031127374 | O4: =H4*$N$1 -> 0.0023325521 | P4: =I4*$N$1 -> 0.0081223118 | Q4: =J4*$N$1 -> 0.015077061 | R4: =K4*$N$1 -> 0.01257929 | S4: =L4*$N$1 -> 0.010219337
D5: M23 | E5: =Sheet1!AH28 -> 0.057975947 | G5: =E5*$E$10 -> 0.0035080163 | H5: =E5*$E$11 -> 0.0026287572 | I5: =E5*$E$12 -> 0.0091537444 | J5: =E5*$E$13 -> 0.01699166 | K5: =E5*$E$14 -> 0.014176703 | L5: =E5*$E$15 -> 0.011517066 | N5: =G5*$N$1 -> 0.0031572147 | O5: =H5*$N$1 -> 0.0023658815 | P5: =I5*$N$1 -> 0.00823837 | Q5: =J5*$N$1 -> 0.015292494 | R5: =K5*$N$1 -> 0.012759033 | S5: =L5*$N$1 -> 0.010365359
D6: N1 | E6: =Sheet1!AH29 -> 0.04828055 | G6: =E6*$E$10 -> 0.0029213659 | H6: =E6*$E$11 -> 0.0021891466 | I6: =E6*$E$12 -> 0.0076229511 | J6: =E6*$E$13 -> 0.014150121 | K6: =E6*$E$14 -> 0.011805914 | L6: =E6*$E$15 -> 0.0095910513 | N6: =G6*$N$1 -> 0.0026292293 | O6: =H6*$N$1 -> 0.0019702319 | P6: =I6*$N$1 -> 0.006860656 | Q6: =J6*$N$1 -> 0.012735109 | R6: =K6*$N$1 -> 0.010625322 | S6: =L6*$N$1 -> 0.0086319461
D7: N2 | E7: =Sheet1!AH30 -> 0.042467045 | G7: =E7*$E$10 -> 0.0025696016 | H7: =E7*$E$11 -> 0.0019255494 | I7: =E7*$E$12 -> 0.0067050647 | J7: =E7*$E$13 -> 0.012446292 | K7: =E7*$E$14 -> 0.010384353 | L7: =E7*$E$15 -> 0.0084361841 | N7: =G7*$N$1 -> 0.0023126414 | O7: =H7*$N$1 -> 0.0017329945 | P7: =I7*$N$1 -> 0.0060345582 | Q7: =J7*$N$1 -> 0.011201663 | R7: =K7*$N$1 -> 0.0093459176 | S7: =L7*$N$1 -> 0.0075925657
D8: N03 | E8: =Sheet1!AH31 -> 0.040164558 | G8: =E8*$E$10 -> 0.0024302824 | H8: =E8*$E$11 -> 0.0018211496 | I8: =E8*$E$12 -> 0.006341528 | J8: =E8*$E$13 -> 0.011771477 | K8: =E8*$E$14 -> 0.0098213318 | L8: =E8*$E$15 -> 0.0079787892 | N8: =G8*$N$1 -> 0.0021872541 | O8: =H8*$N$1 -> 0.0016390346 | P8: =I8*$N$1 -> 0.0057073752 | Q8: =J8*$N$1 -> 0.010594329 | R8: =K8*$N$1 -> 0.0088391986 | S8: =L8*$N$1 -> 0.0071809103
C10: IT | D10: 0.0017984376 | E10: =D10/$D$16 -> 0.060508132
C11: GB | D11: 0.0013476722 | E11: =D11/$D$16 -> 0.045342204
C12: DE | D12: 0.0046928056 | E12: =D12/$D$16 -> 0.15788866
C13: CH | D13: 0.0087110317 | E13: =D13/$D$16 -> 0.2930812
C14: BE | D14: 0.0072679015 | E14: =D14/$D$16 -> 0.24452732
C15: ES | D15: 0.0059043982 | E15: =D15/$D$16 -> 0.19865249
D16: =SUM(D10:D15) -> 0.029722247
A18: Source: IEA World Energy Balances https://www.iea.org/data-and-statistics/data-product/world-energy-statistics-and-balances
A19: Documentation: undefined
A20: This data is subject to the IEA's terms and conditions: https://www.iea.org/terms
B22: Imports | C22: Exports | D22: Units | E22: TWh | F22: TWh
A23: 1990 | B23: 24026 | C23: -187603 | D23: TJ | E23: =B23*0.00027777777777778 -> 6.6738889 | F23: =C23*0.00027777777777778 -> -52.111944
A24: 1995 | B24: 10295 | C24: -261723 | D24: TJ | E24: =B24*0.00027777777777778 -> 2.8597222 | F24: =C24*0.00027777777777778 -> -72.700833
A25: 2000 | B25: 13302 | C25: -263426 | D25: TJ | E25: =B25*0.00027777777777778 -> 3.695 | F25: =C25*0.00027777777777778 -> -73.173889
A26: 2005 | B26: 29023 | C26: -246203 | D26: TJ | E26: =B26*0.00027777777777778 -> 8.0619444 | F26: =C26*0.00027777777777778 -> -68.389722
A27: 2010 | B27: 70110 | C27: -180676 | D27: TJ | E27: =B27*0.00027777777777778 -> 19.475 | F27: =C27*0.00027777777777778 -> -50.187778
A28: 2015 | B28: 35859 | C28: -266486 | D28: TJ | E28: =B28*0.00027777777777778 -> 9.9608333 | F28: =C28*0.00027777777777778 -> -74.023889
A29: 2019 | B29: 56274 | C29: -263875 | D29: TJ | E29: =B29*0.00027777777777778 -> 15.631667 | F29: =C29*0.00027777777777778 -> -73.298611 | G29: from the plot
A30: 2020 | B30: 70329 | C30: -232471 | D30: TJ | E30: =B30*0.00027777777777778 -> 19.535833 | F30: =C30*0.00027777777777778 -> -64.575278
A31: 2022 | B31: 188815 | C31: -134401 | D31: TJ | E31: =B31*0.00027777777777778 -> 52.448611 | F31: =C31*0.00027777777777778 -> -37.333611
